<?xml version="1.0" encoding="utf-8"?>
<robot name="a1">
  <material name="orange">
    <color rgba="1.0 0.423529411765 0.0392156862745 1.0"/>
  </material>
  <link name="TORSO">
    <visual>
      <geometry>
        <mesh filename="../meshes/trunk.stl"/>
      </geometry>
      <material name="orange"/>
    </visual>
    <collision>
      <geometry>
        <box size="0.367 0.194 0.114"/>
      </geometry>
    </collision>
    <inertial>
      <origin xyz="0.012731 0.002186 0.000515"/>
      <mass value="4.713"/>
      <inertia ixx="0.01683993" ixy="8.3902e-05" ixz="0.000597679"
               iyy="0.056579028" iyz="2.5134e-05" izz="0.064713601"/>
    </inertial>
  </link>

  <link name="FL_HIP">
    <inertial>
      <origin xyz="-0.003311 0.000635 3.1e-05"/>
      <mass value="0.696"/>
      <inertia ixx="0.000469246" ixy="-9.409e-06" ixz="-3.42e-07"
               iyy="0.00080749" iyz="-4.66e-07" izz="0.000552929"/>
    </inertial>
    <visual>
      <geometry>
        <mesh filename="../meshes/hip.stl"/>
      </geometry>
      <material name="orange"/>
    </visual>
  </link>

  <joint name="FL_HipX" type="revolute">
    <origin xyz="0.183 0.047 0"/>
    <parent link="TORSO"/>
    <child link="FL_HIP"/>
    <axis xyz="1 0 0"/>
    <limit effort="20" lower="-0.802851455917" upper="0.802851455917" velocity="20"/>
  </joint>

  <link name="FL_THIGH">
    <inertial>
      <origin xyz="-0.003237 -0.022327 -0.027326"/>
      <mass value="1.013"/>
      <inertia ixx="0.005529065" ixy="4.825e-06" ixz="0.000343869"
               iyy="0.005139339" iyz="2.2448e-05" izz="0.001367788"/>
    </inertial>
    <visual>
      <geometry>
        <mesh filename="../meshes/thigh.stl"/>
      </geometry>
      <material name="orange"/>
    </visual>
    <collision>
      <origin rpy="0 1.57079632679 0" xyz="0 0 -0.1"/>
      <geometry>
        <box size="0.2 0.0245 0.034"/>
      </geometry>
    </collision>
  </link>

  <joint name="FL_HipY" type="continuous">
    <origin xyz="0 0.08505 0"/>
    <parent link="FL_HIP"/>
    <child link="FL_THIGH"/>
    <axis xyz="0 -1 0"/>
    <limit effort="55" lower="-4.18879020479" upper="1.0471975512" velocity="20"/>
  </joint>

  <link name="FL_SHANK">
    <inertial>
      <origin xyz="0.006435 0.0 -0.107388"/>
      <mass value="0.166"/>
      <inertia ixx="0.002997972" ixy="0.0" ixz="-0.000141163"
               iyy="0.003014022" iyz="0.0" izz="3.2426e-05"/>
    </inertial>
    <visual>
      <geometry>
        <mesh filename="../meshes/calf.stl"/>
      </geometry>
      <material name="orange"/>
    </visual>
    <collision>
      <origin rpy="0 1.57079632679 0" xyz="0 0 -0.1"/>
      <geometry>
        <box size="0.2 0.016 0.016"/>
      </geometry>
    </collision>
  </link>

  <joint name="FL_Knee" type="revolute">
    <origin xyz="0 0 -0.20"/>
    <parent link="FL_THIGH"/>
    <child link="FL_SHANK"/>
    <axis xyz="0 -1 0"/>
    <limit effort="55" lower="0.916297857297" upper="2.69653369433" velocity="20"/>
  </joint>

  <link name="FL_FOOT">
    <inertial>
      <mass value="0.06"/>
      <inertia ixx="9.6e-06" ixy="0.0" ixz="0.0" iyy="9.6e-06" iyz="0.0" izz="9.6e-06"/>
    </inertial>
    <visual>
      <geometry>
        <sphere radius="0.02"/>
      </geometry>
      <material name="orange"/>
    </visual>
    <collision>
      <geometry>
        <sphere radius="0.02"/>
      </geometry>
    </collision>
  </link>

  <joint name="FL_Ankle" type="fixed">
    <origin xyz="0 0 -0.2"/>
    <parent link="FL_SHANK"/>
    <child link="FL_FOOT"/>
  </joint>

  <link name="FR_HIP">
    <inertial>
      <origin xyz="-0.003311 -0.000635 3.1e-05"/>
      <mass value="0.696"/>
      <inertia ixx="0.000469246" ixy="9.409e-06" ixz="-3.42e-07"
               iyy="0.00080749" iyz="4.66e-07" izz="0.000552929"/>
    </inertial>
    <visual>
      <geometry>
        <mesh filename="../meshes/hip.stl"/>
      </geometry>
      <material name="orange"/>
    </visual>
  </link>

  <joint name="FR_HipX" type="revolute">
    <origin xyz="0.183 -0.047 0"/>
    <parent link="TORSO"/>
    <child link="FR_HIP"/>
<!--    <axis xyz="-1 0 0"/>-->
    <axis xyz="1 0 0"/>
    <limit effort="20" lower="-0.802851455917" upper="0.802851455917" velocity="20"/>
  </joint>

  <link name="FR_THIGH">
    <inertial>
      <origin rpy="0 0 0" xyz="-0.003237 0.022327 -0.027326"/>
      <mass value="1.013"/>
      <inertia ixx="0.005529065" ixy="-4.825e-06" ixz="0.000343869"
               iyy="0.005139339" iyz="-2.2448e-05" izz="0.001367788"/>
    </inertial>
    <visual>
      <geometry>
        <mesh filename="../meshes/thigh_mirror.stl"/>
      </geometry>
      <material name="orange"/>
    </visual>
    <collision>
      <origin rpy="0 1.57079632679 0" xyz="0 0 -0.1"/>
      <geometry>
        <box size="0.2 0.0245 0.034"/>
      </geometry>
    </collision>
  </link>

  <joint name="FR_HipY" type="continuous">
    <origin xyz="0 -0.08505 0"/>
    <parent link="FR_HIP"/>
    <child link="FR_THIGH"/>
    <axis xyz="0 -1 0"/>
    <limit effort="55" lower="-4.18879020479" upper="1.0471975512" velocity="20"/>
  </joint>

  <link name="FR_SHANK">
    <inertial>
      <origin rpy="0 0 0" xyz="0.006435 0.0 -0.107388"/>
      <mass value="0.166"/>
      <inertia ixx="0.002997972" ixy="0.0" ixz="-0.000141163" iyy="0.003014022" iyz="0.0" izz="3.2426e-05"/>
    </inertial>
    <visual>
      <geometry>
        <mesh filename="../meshes/calf.stl"/>
      </geometry>
      <material name="orange"/>
    </visual>
    <collision>
      <origin rpy="0 1.57079632679 0" xyz="0 0 -0.1"/>
      <geometry>
        <box size="0.2 0.016 0.016"/>
      </geometry>
    </collision>
  </link>

  <joint name="FR_Knee" type="revolute">
    <origin xyz="0 0 -0.20"/>
    <parent link="FR_THIGH"/>
    <child link="FR_SHANK"/>
    <axis xyz="0 -1 0"/>
    <limit effort="55" lower="0.916297857297" upper="2.69653369433" velocity="20"/>
  </joint>

  <link name="FR_FOOT">
    <inertial>
      <mass value="0.06"/>
      <inertia ixx="9.6e-06" ixy="0.0" ixz="0.0" iyy="9.6e-06" iyz="0.0" izz="9.6e-06"/>
    </inertial>
    <visual>
      <geometry>
        <sphere radius="0.02"/>
      </geometry>
      <material name="orange"/>
    </visual>
    <collision>
      <geometry>
        <sphere radius="0.02"/>
      </geometry>
    </collision>
  </link>

  <joint name="FR_Ankle" type="fixed">
    <origin xyz="0 0 -0.2"/>
    <parent link="FR_SHANK"/>
    <child link="FR_FOOT"/>
  </joint>

  <link name="HL_HIP">
    <inertial>
      <origin rpy="0 0 0" xyz="0.003311 0.000635 3.1e-05"/>
      <mass value="0.696"/>
      <inertia ixx="0.000469246" ixy="9.409e-06" ixz="3.42e-07" iyy="0.00080749" iyz="-4.66e-07" izz="0.000552929"/>
    </inertial>
    <visual>
      <origin rpy="0 3.14159265359 0" xyz="0 0 0"/>
      <geometry>
        <mesh filename="../meshes/hip.stl"/>
      </geometry>
      <material name="orange"/>
    </visual>
  </link>

  <joint name="HL_HipX" type="revolute">
    <origin xyz="-0.183 0.047 0"/>
    <parent link="TORSO"/>
    <child link="HL_HIP"/>
    <axis xyz="1 0 0"/>
    <limit effort="20" lower="-0.802851455917" upper="0.802851455917" velocity="20"/>
  </joint>

  <link name="HL_THIGH">
    <inertial>
      <origin rpy="0 0 0" xyz="-0.003237 -0.022327 -0.027326"/>
      <mass value="1.013"/>
      <inertia ixx="0.005529065" ixy="4.825e-06" ixz="0.000343869"
               iyy="0.005139339" iyz="2.2448e-05" izz="0.001367788"/>
    </inertial>
    <visual>
      <geometry>
        <mesh filename="../meshes/thigh.stl"/>
      </geometry>
      <material name="orange"/>
    </visual>
    <collision>
      <origin rpy="0 1.57079632679 0" xyz="0 0 -0.1"/>
      <geometry>
        <box size="0.2 0.0245 0.034"/>
      </geometry>
    </collision>
  </link>

  <joint name="HL_HipY" type="continuous">
    <origin rpy="0 0 0" xyz="0 0.08505 0"/>
    <parent link="HL_HIP"/>
    <child link="HL_THIGH"/>
    <axis xyz="0 -1 0"/>
    <limit effort="55" lower="-4.18879020479" upper="1.0471975512" velocity="20"/>
  </joint>

  <link name="HL_SHANK">
    <inertial>
      <origin rpy="0 0 0" xyz="0.006435 0.0 -0.107388"/>
      <mass value="0.166"/>
      <inertia ixx="0.002997972" ixy="0.0" ixz="-0.000141163" iyy="0.003014022" iyz="0.0" izz="3.2426e-05"/>
    </inertial>
    <visual>
      <geometry>
        <mesh filename="../meshes/calf.stl"/>
      </geometry>
      <material name="orange"/>
    </visual>
    <collision>
      <origin rpy="0 1.57079632679 0" xyz="0 0 -0.1"/>
      <geometry>
        <box size="0.2 0.016 0.016"/>
      </geometry>
    </collision>
  </link>

  <joint name="HL_Knee" type="revolute">
    <origin xyz="0 0 -0.20"/>
    <parent link="HL_THIGH"/>
    <child link="HL_SHANK"/>
    <axis xyz="0 -1 0"/>
    <limit effort="55" lower="0.916297857297" upper="2.69653369433" velocity="20"/>
  </joint>

  <link name="HL_FOOT">
    <inertial>
      <mass value="0.06"/>
      <inertia ixx="9.6e-06" ixy="0.0" ixz="0.0" iyy="9.6e-06" iyz="0.0" izz="9.6e-06"/>
    </inertial>
    <visual>
      <geometry>
        <sphere radius="0.02"/>
      </geometry>
      <material name="orange"/>
    </visual>
    <collision>
      <geometry>
        <sphere radius="0.02"/>
      </geometry>
    </collision>
  </link>

  <joint name="HL_Ankle" type="fixed">
    <origin xyz="0 0 -0.2"/>
    <parent link="HL_SHANK"/>
    <child link="HL_FOOT"/>
  </joint>

  <link name="HR_HIP">
    <inertial>
      <origin rpy="0 0 0" xyz="0.003311 -0.000635 3.1e-05"/>
      <mass value="0.696"/>
      <inertia ixx="0.000469246" ixy="-9.409e-06" ixz="3.42e-07"
               iyy="0.00080749" iyz="4.66e-07" izz="0.000552929"/>
    </inertial>
    <visual>
      <origin rpy="3.14159265359 3.14159265359 0" xyz="0 0 0"/>
      <geometry>
        <mesh filename="../meshes/hip.stl"/>
      </geometry>
      <material name="orange"/>
    </visual>
  </link>

  <joint name="HR_HipX" type="revolute">
    <origin rpy="0 0 0" xyz="-0.183 -0.047 0"/>
    <parent link="TORSO"/>
    <child link="HR_HIP"/>
    <axis xyz="1 0 0"/>
<!--    <axis xyz="-1 0 0"/>-->
    <limit effort="20" lower="-0.802851455917" upper="0.802851455917" velocity="20"/>
  </joint>

  <link name="HR_THIGH">
    <inertial>
      <origin rpy="0 0 0" xyz="-0.003237 0.022327 -0.027326"/>
      <mass value="1.013"/>
      <inertia ixx="0.005529065" ixy="-4.825e-06" ixz="0.000343869"
               iyy="0.005139339" iyz="-2.2448e-05" izz="0.001367788"/>
    </inertial>
    <visual>
      <geometry>
        <mesh filename="../meshes/thigh_mirror.stl"/>
      </geometry>
      <material name="orange"/>
    </visual>
    <collision>
      <origin rpy="0 1.57079632679 0" xyz="0 0 -0.1"/>
      <geometry>
        <box size="0.2 0.0245 0.034"/>
      </geometry>
    </collision>
  </link>

  <joint name="HR_HipY" type="continuous">
    <origin xyz="0 -0.08505 0"/>
    <parent link="HR_HIP"/>
    <child link="HR_THIGH"/>
    <axis xyz="0 -1 0"/>
    <limit effort="55" lower="-4.18879020479" upper="1.0471975512" velocity="20"/>
  </joint>

  <link name="HR_SHANK">
    <inertial>
      <origin rpy="0 0 0" xyz="0.006435 0.0 -0.107388"/>
      <mass value="0.166"/>
      <inertia ixx="0.002997972" ixy="0.0" ixz="-0.000141163"
               iyy="0.003014022" iyz="0.0" izz="3.2426e-05"/>
    </inertial>
    <visual>
      <geometry>
        <mesh filename="../meshes/calf.stl"/>
      </geometry>
      <material name="orange"/>
    </visual>
    <collision>
      <origin rpy="0 1.57079632679 0" xyz="0 0 -0.1"/>
      <geometry>
        <box size="0.2 0.016 0.016"/>
      </geometry>
    </collision>
  </link>

  <joint name="HR_Knee" type="revolute">
    <origin xyz="0 0 -0.20"/>
    <parent link="HR_THIGH"/>
    <child link="HR_SHANK"/>
    <axis xyz="0 -1 0"/>
    <limit effort="55" lower="0.916297857297" upper="2.69653369433" velocity="20"/>
  </joint>

  <link name="HR_FOOT">
    <inertial>
      <mass value="0.06"/>
      <inertia ixx="9.6e-06" ixy="0.0" ixz="0.0" iyy="9.6e-06" iyz="0.0" izz="9.6e-06"/>
    </inertial>
    <visual>
      <origin rpy="0 0 0" xyz="0 0 0"/>
      <geometry>
        <sphere radius="0.01"/>
      </geometry>
      <material name="orange"/>
    </visual>
    <collision>
      <geometry>
        <sphere radius="0.02"/>
      </geometry>
    </collision>
  </link>

  <joint name="HR_Ankle" type="fixed">
    <origin xyz="0 0 -0.2"/>
    <parent link="HR_SHANK"/>
    <child link="HR_FOOT"/>
  </joint>

</robot>
