<?xml version="1.0" ?>
<!-- =================================================================================== -->
<!-- |    This document was autogenerated by xacro from robot.xacro                    | -->
<!-- |    EDITING THIS FILE BY HAND IS NOT RECOMMENDED                                 | -->
<!-- =================================================================================== -->
<robot name="aliengoZ1_description">
  <material name="black">
    <color rgba="0.0 0.0 0.0 1.0"/>
  </material>
  <material name="blue">
    <color rgba="0.0 0.0 0.8 1.0"/>
  </material>
  <material name="green">
    <color rgba="0.0 0.8 0.0 1.0"/>
  </material>
  <material name="grey">
    <color rgba="0.2 0.2 0.2 1.0"/>
  </material>
  <material name="silver">
    <color rgba="0.9137254901960784 0.9137254901960784 0.8470588235294118 1.0"/>
  </material>
  <material name="orange">
    <color rgba="1.0 0.4235294117647059 0.0392156862745098 1.0"/>
  </material>
  <material name="brown">
    <color rgba="0.8705882352941177 0.8117647058823529 0.7647058823529411 1.0"/>
  </material>
  <material name="red">
    <color rgba="0.8 0.0 0.0 1.0"/>
  </material>
  <material name="white">
    <color rgba="1.0 1.0 1.0 1.0"/>
  </material>
  <!-- Debug mode will hung up the robot, use "true" or "false" to switch it. -->
  <!-- <xacro:if value="$(arg DEBUG)">
        <link name="world"/>
        <joint name="base_static_joint" type="fixed">
            <origin rpy="0 0 0" xyz="0 0 0"/>
            <parent link="world"/>
            <child link="base"/>
        </joint>
    </xacro:if>  -->
  <link name="base">
    <visual>
      <origin rpy="0 0 0" xyz="0 0 0"/>
      <geometry>
        <box size="0.001 0.001 0.001"/>
      </geometry>
    </visual>
  </link>
  <joint name="floating_base" type="fixed">
    <origin rpy="0 0 0" xyz="0 0 0"/>
    <parent link="base"/>
    <child link="trunk"/>
  </joint>
  <link name="trunk">
    <visual>
      <origin rpy="0 0 0" xyz="0 0 0"/>
      <geometry>
        <mesh filename="meshes/visual/trunk.dae" scale="1 1 1"/>
      </geometry>
      <!-- <material name="orange"/> -->
    </visual>
    <collision>
      <origin rpy="0 0 0" xyz="0 0 0"/>
      <geometry>
        <box size="0.647 0.15 0.112"/>
      </geometry>
    </collision>
    <inertial>
      <origin rpy="0 0 0" xyz="0.008811 0.003839 0.000273"/>
      <mass value="11.644"/>
      <inertia ixx="0.051944892" ixy="0.001703617" ixz="0.000235941" iyy="0.24693924" iyz="0.000119783" izz="0.270948307"/>
    </inertial>
  </link>
  <joint name="imu_joint" type="fixed">
    <parent link="trunk"/>
    <child link="imu_link"/>
    <origin rpy="0 0 0" xyz="0 0 0"/>
  </joint>
  <link name="imu_link">
    <inertial>
      <mass value="0.001"/>
      <origin rpy="0 0 0" xyz="0 0 0"/>
      <inertia ixx="0.0001" ixy="0" ixz="0" iyy="0.000001" iyz="0" izz="0.0001"/>
    </inertial>
    <visual>
      <origin rpy="0 0 0" xyz="0 0 0"/>
      <geometry>
        <box size="0.001 0.001 0.001"/>
      </geometry>
      <!-- <material name="red"/> -->
    </visual>
    <collision>
      <origin rpy="0 0 0" xyz="0 0 0"/>
      <geometry>
        <box size=".001 .001 .001"/>
      </geometry>
    </collision>
  </link>
   --&gt;


  <joint name="trunk_arm_joint" type="fixed">
    <origin rpy="0 0 0" xyz="0.2535 0 0.056"/>
    <parent link="trunk"/>
    <child link="link00"/>
  </joint>
  <link name="link00">
    <visual>
      <origin rpy="0 0 0" xyz="0 0 0"/>
      <geometry>
        <mesh filename="meshes/visual/z1_Link00.dae" scale="1 1 1"/>
      </geometry>
    </visual>
    <collision>
      <geometry>
        <cylinder length="0.051" radius="0.0325"/>
      </geometry>
      <origin rpy="0 0 0" xyz="0 0 0.0255"/>
    </collision>
    <inertial>
      <origin rpy="0 0 0" xyz="-0.00334984 -0.00013615 0.02495843"/>
      <mass value="0.47247481"/>
      <inertia ixx="0.00037937" ixy="-3.5e-07" ixz="-1.037e-05" iyy="0.00041521" iyz="-9.9e-07" izz="0.00053066"/>
    </inertial>
  </link>
  <joint name="joint1" type="revolute">
    <origin rpy="0 0 0" xyz="0 0 0.0585"/>
    <parent link="link00"/>
    <child link="link01"/>
    <axis xyz="0 0 1"/>
    <dynamics damping="1.0" friction="1.0"/>
    <limit effort="30.0" lower="-2.6179938779914944" upper="2.6179938779914944" velocity="3.1415"/>
  </joint>
  <link name="link01">
    <visual>
      <origin rpy="0 0 0" xyz="0 0 0"/>
      <geometry>
        <mesh filename="meshes/visual/z1_Link01.dae" scale="1 1 1"/>
      </geometry>
    </visual>
    <collision>
      <geometry>
        <cylinder length="0.102" radius="0.0325"/>
      </geometry>
      <origin rpy="0 0 0" xyz="0 0 0"/>
    </collision>
    <inertial>
      <origin rpy="0 0 0" xyz="2.47e-06 -0.00025198 0.02317169"/>
      <mass value="0.67332551"/>
      <inertia ixx="0.00128328" ixy="-6e-08" ixz="-4e-07" iyy="0.00071931" iyz="5e-07" izz="0.00083936"/>
    </inertial>
  </link>
  <joint name="joint2" type="revolute">
    <origin rpy="0 0 0" xyz="0 0 0.045"/>
    <parent link="link01"/>
    <child link="link02"/>
    <axis xyz="0 1 0"/>
    <dynamics damping="2.0" friction="2.0"/>
    <limit effort="60.0" lower="0.0" upper="2.9670597283903604" velocity="3.1415"/>
  </joint>
  <link name="link02">
    <visual>
      <origin rpy="0 0 0" xyz="0 0 0"/>
      <geometry>
        <mesh filename="meshes/visual/z1_Link02.dae" scale="1 1 1"/>
      </geometry>
    </visual>
    <collision>
      <geometry>
        <cylinder length="0.102" radius="0.0325"/>
      </geometry>
      <origin rpy="1.5707963267948966 0 0" xyz="0 0 0"/>
    </collision>
    <collision>
      <geometry>
        <cylinder length="0.235" radius="0.0225"/>
      </geometry>
      <origin rpy="0 1.5707963267948966 0" xyz="-0.16249999999999998 0 0"/>
    </collision>
    <collision>
      <geometry>
        <cylinder length="0.051" radius="0.0325"/>
      </geometry>
      <origin rpy="1.5707963267948966 0 0" xyz="-0.35 0 0"/>
    </collision>
    <inertial>
      <origin rpy="0 0 0" xyz="-0.11012601 0.00240029 0.00158266"/>
      <mass value="1.19132258"/>
      <inertia ixx="0.00102138" ixy="0.00062358" ixz="5.13e-06" iyy="0.02429457" iyz="-2.1e-06" izz="0.02466114"/>
    </inertial>
  </link>
  <joint name="joint3" type="revolute">
    <origin rpy="0 0 0" xyz="-0.35 0 0"/>
    <parent link="link02"/>
    <child link="link03"/>
    <axis xyz="0 1 0"/>
    <dynamics damping="1.0" friction="1.0"/>
    <limit effort="30.0" lower="-2.8797932657906435" upper="0.0" velocity="3.1415"/>
  </joint>
  <link name="link03">
    <visual>
      <origin rpy="0 0 0" xyz="0 0 0"/>
      <geometry>
        <mesh filename="meshes/visual/z1_Link03.dae" scale="1 1 1"/>
      </geometry>
    </visual>
    <collision>
      <geometry>
        <cylinder length="0.116" radius="0.02"/>
      </geometry>
      <origin rpy="0 1.5707963267948966 0" xyz="0.128 0 0.055"/>
    </collision>
    <collision>
      <geometry>
        <cylinder length="0.059" radius="0.0325"/>
      </geometry>
      <origin rpy="0 1.5707963267948966 1.5707963267948966" xyz="0.2205 0 0.055"/>
    </collision>
    <inertial>
      <origin rpy="0 0 0" xyz="0.10609208 -0.00541815 0.03476383"/>
      <mass value="0.83940874"/>
      <inertia ixx="0.00108061" ixy="-8.669e-05" ixz="-0.00208102" iyy="0.00954238" iyz="-1.332e-05" izz="0.00886621"/>
    </inertial>
  </link>
  <joint name="joint4" type="revolute">
    <origin rpy="0 0 0" xyz="0.218 0 0.057"/>
    <parent link="link03"/>
    <child link="link04"/>
    <axis xyz="0 1 0"/>
    <dynamics damping="1.0" friction="1.0"/>
    <limit effort="30.0" lower="-1.5184364492350666" upper="1.5184364492350666" velocity="3.1415"/>
  </joint>
  <link name="link04">
    <visual>
      <origin rpy="0 0 0" xyz="0 0 0"/>
      <geometry>
        <mesh filename="meshes/visual/z1_Link04.dae" scale="1 1 1"/>
      </geometry>
    </visual>
    <collision>
      <geometry>
        <cylinder length="0.067" radius="0.0325"/>
      </geometry>
      <origin rpy="0 0 0" xyz="0.072 0 0"/>
    </collision>
    <inertial>
      <origin rpy="0 0 0" xyz="0.04366681 0.00364738 -0.00170192"/>
      <mass value="0.56404563"/>
      <inertia ixx="0.00031576" ixy="8.13e-05" ixz="4.091e-05" iyy="0.00092996" iyz="-5.96e-06" izz="0.00097912"/>
    </inertial>
  </link>
  <joint name="joint5" type="revolute">
    <origin rpy="0 0 0" xyz="0.07 0.0 0.0"/>
    <parent link="link04"/>
    <child link="link05"/>
    <axis xyz="0 0 1"/>
    <dynamics damping="1.0" friction="1.0"/>
    <limit effort="30.0" lower="-1.3439035240356338" upper="1.3439035240356338" velocity="3.1415"/>
  </joint>
  <link name="link05">
    <visual>
      <origin rpy="0 0 0" xyz="0 0 0"/>
      <geometry>
        <mesh filename="meshes/visual/z1_Link05.dae" scale="1 1 1"/>
      </geometry>
    </visual>
    <inertial>
      <origin rpy="0 0 0" xyz="0.03121533 0.0 0.00646316"/>
      <mass value="0.38938492"/>
      <inertia ixx="0.00017605" ixy="4e-07" ixz="5.689e-05" iyy="0.00055896" iyz="-1.3e-07" izz="0.0005386"/>
    </inertial>
  </link>
  <joint name="joint6" type="revolute">
    <origin rpy="0 0 0" xyz="0.0492 0.0 0.0"/>
    <parent link="link05"/>
    <child link="link06"/>
    <axis xyz="1 0 0"/>
    <dynamics damping="1.0" friction="1.0"/>
    <limit effort="30.0" lower="-2.792526803190927" upper="2.792526803190927" velocity="3.1415"/>
  </joint>
  <link name="link06">
    <visual>
      <origin rpy="0 0 0" xyz="0 0 0"/>
      <geometry>
        <mesh filename="meshes/visual/z1_Link06.dae" scale="1 1 1"/>
      </geometry>
    </visual>
    <collision>
      <geometry>
        <cylinder length="0.051" radius="0.0325"/>
      </geometry>
      <origin rpy="0 1.5707963267948966 0" xyz="0.0255 0 0"/>
    </collision>
    <inertial>
      <origin rpy="0 0 0" xyz="0.0241569 -0.00017355 -0.00143876"/>
      <mass value="0.28875807"/>
      <inertia ixx="0.00018328" ixy="1.22e-06" ixz="5.4e-07" iyy="0.0001475" iyz="8e-08" izz="0.0001468"/>
    </inertial>
  </link>
  <joint name="gripperStator" type="fixed">
    <origin rpy="0 0 0" xyz="0.051 0.0 0.0"/>
    <parent link="link06"/>
    <child link="gripperStator"/>
  </joint>
  <link name="gripperStator">
    <visual>
      <geometry>
        <mesh filename="meshes/visual/z1_GripperStator.dae" scale="1 1 1"/>
      </geometry>
    </visual>
    <collision>
      <geometry>
        <mesh filename="meshes/collision/z1_GripperStator.obj" scale="1 1 1"/>
      </geometry>
    </collision>
    <inertial>
      <origin rpy="0 0 0" xyz="0.04764427 -0.00035819 -0.00249162"/>
      <mass value="0.52603655"/>
      <inertia ixx="0.00038683" ixy="-3.59e-06" ixz="7.662e-05" iyy="0.00068614" iyz="2.09e-06" izz="0.00066293"/>
    </inertial>
  </link>
  <joint name="jointGripper" type="fixed">
    <origin rpy="0 0 0" xyz="0.049 0.0 0"/>
    <parent link="gripperStator"/>
    <child link="gripperMover"/>
    <axis xyz="0 1 0"/>
    <dynamics damping="1.0" friction="1.0"/>
    <limit effort="30.0" lower="-1.5707963267948966" upper="0.0" velocity="3.1415"/>
  </joint>
  <link name="gripperMover">
    <visual>
      <geometry>
        <mesh filename="meshes/visual/z1_GripperMover.dae" scale="1 1 1"/>
      </geometry>
    </visual>
    <collision>
      <geometry>
        <mesh filename="meshes/collision/z1_GripperMover.obj" scale="1 1 1"/>
      </geometry>
    </collision>
    <inertial>
      <origin rpy="0 0 0" xyz="0.01320633 0.00476708 0.00380534"/>
      <mass value="0.27621302"/>
      <inertia ixx="0.00017716" ixy="1.683e-05" ixz="-1.786e-05" iyy="0.00026787" iyz="2.62e-06" izz="0.00035728"/>
    </inertial>
  </link>
  <!-- <transmission name="JointTransGripper">
    <type>transmission_interface/SimpleTransmission</type>
    <joint name="jointGripper">
      <hardwareInterface>hardware_interface/EffortJointInterface</hardwareInterface>
    </joint>
    <actuator name="ActuatorGripper">
      <hardwareInterface>hardware_interface/EffortJointInterface</hardwareInterface>
      <mechanicalReduction>1</mechanicalReduction>
    </actuator>
  </transmission> -->
  <gazebo reference="gripperStator">
    <self_collide>true</self_collide>
  </gazebo>
  <gazebo reference="gripperMover">
    <self_collide>true</self_collide>
  </gazebo>
  <transmission name="JointTrans1">
    <type>transmission_interface/SimpleTransmission</type>
    <joint name="joint1">
      <hardwareInterface>hardware_interface/EffortJointInterface</hardwareInterface>
    </joint>
    <actuator name="Actuator1">
      <hardwareInterface>hardware_interface/EffortJointInterface</hardwareInterface>
      <mechanicalReduction>1</mechanicalReduction>
    </actuator>
  </transmission>
  <transmission name="JointTrans2">
    <type>transmission_interface/SimpleTransmission</type>
    <joint name="joint2">
      <hardwareInterface>hardware_interface/EffortJointInterface</hardwareInterface>
    </joint>
    <actuator name="Actuator2">
      <hardwareInterface>hardware_interface/EffortJointInterface</hardwareInterface>
      <mechanicalReduction>1</mechanicalReduction>
    </actuator>
  </transmission>
  <transmission name="JointTrans3">
    <type>transmission_interface/SimpleTransmission</type>
    <joint name="joint3">
      <hardwareInterface>hardware_interface/EffortJointInterface</hardwareInterface>
    </joint>
    <actuator name="Actuator3">
      <hardwareInterface>hardware_interface/EffortJointInterface</hardwareInterface>
      <mechanicalReduction>1</mechanicalReduction>
    </actuator>
  </transmission>
  <transmission name="JointTrans4">
    <type>transmission_interface/SimpleTransmission</type>
    <joint name="joint4">
      <hardwareInterface>hardware_interface/EffortJointInterface</hardwareInterface>
    </joint>
    <actuator name="Actuator4">
      <hardwareInterface>hardware_interface/EffortJointInterface</hardwareInterface>
      <mechanicalReduction>1</mechanicalReduction>
    </actuator>
  </transmission>
  <transmission name="JointTrans5">
    <type>transmission_interface/SimpleTransmission</type>
    <joint name="joint5">
      <hardwareInterface>hardware_interface/EffortJointInterface</hardwareInterface>
    </joint>
    <actuator name="Actuator5">
      <hardwareInterface>hardware_interface/EffortJointInterface</hardwareInterface>
      <mechanicalReduction>1</mechanicalReduction>
    </actuator>
  </transmission>
  <transmission name="JointTrans6">
    <type>transmission_interface/SimpleTransmission</type>
    <joint name="joint6">
      <hardwareInterface>hardware_interface/EffortJointInterface</hardwareInterface>
    </joint>
    <actuator name="Actuator6">
      <hardwareInterface>hardware_interface/EffortJointInterface</hardwareInterface>
      <mechanicalReduction>1</mechanicalReduction>
    </actuator>
  </transmission>
  <joint name="FR_hip_joint" type="revolute">
    <origin rpy="0 0 0" xyz="0.2407 -0.051 0"/>
    <parent link="trunk"/>
    <child link="FR_hip"/>
    <axis xyz="1 0 0"/>
    <dynamics damping="0" friction="0"/>
    <limit effort="35.278" lower="-1.2217304763960306" upper="1.2217304763960306" velocity="20"/>
  </joint>
  <joint name="FR_hip_rotor_joint" type="fixed">
    <origin rpy="0 0 0" xyz="0.139985 -0.051 0"/>
    <parent link="trunk"/>
    <child link="FR_hip_rotor"/>
  </joint>
  <link name="FR_hip">
    <visual>
      <origin rpy="3.141592653589793 0 0" xyz="0 0 0"/>
      <geometry>
        <mesh filename="meshes/visual/hip.dae" scale="1 1 1"/>
      </geometry>
      <!-- <material name="orange"/> -->
    </visual>
    <collision>
      <origin rpy="1.5707963267948966 0 0" xyz="0 -0.083 0"/>
      <geometry>
        <cylinder length="0.0418" radius="0.046"/>
      </geometry>
    </collision>
    <inertial>
      <origin rpy="0 0 0" xyz="-0.022191 -0.015144 -1.5e-05"/>
      <mass value="1.993"/>
      <inertia ixx="0.002446735" ixy="0.00059805" ixz="1.945e-06" iyy="0.003925876" iyz="-1.284e-06" izz="0.004148145"/>
    </inertial>
  </link>
  <link name="FR_hip_rotor">
    <visual>
      <origin rpy="0 1.5707963267948966 0" xyz="0 0 0"/>
      <geometry>
        <cylinder length="0.02" radius="0.035"/>
      </geometry>
      <!-- <material name="green"/> -->
    </visual>
    <!-- <collision>
                <origin rpy="0 ${PI/2.0} 0" xyz="0 0 0"/>
                <geometry>
                    <cylinder length="0.02" radius="0.035"/>
                </geometry>
            </collision> -->
    <inertial>
      <origin rpy="0 0 0" xyz="0.0 0.0 0.0"/>
      <mass value="0.146"/>
      <inertia ixx="0.000138702" ixy="0.0" ixz="0.0" iyy="8.3352e-05" iyz="0.0" izz="8.3352e-05"/>
    </inertial>
  </link>
  <joint name="FR_thigh_joint" type="continuous">
    <origin rpy="0 0 0" xyz="0 -0.0868 0"/>
    <parent link="FR_hip"/>
    <child link="FR_thigh"/>
    <axis xyz="0 1 0"/>
    <dynamics damping="0" friction="0"/>
    <limit effort="35.278" velocity="20"/>
  </joint>
  <joint name="FR_thigh_rotor_joint" type="fixed">
    <origin rpy="0 0 0" xyz="0.0 -0.0298 0"/>
    <parent link="FR_hip"/>
    <child link="FR_thigh_rotor"/>
  </joint>
  <link name="FR_thigh">
    <visual>
      <origin rpy="0 0 0" xyz="0 0 0"/>
      <geometry>
        <mesh filename="meshes/visual/thigh_mirror.dae" scale="1 1 1"/>
      </geometry>
      <!-- <material name="orange"/> -->
    </visual>
    <collision>
      <origin rpy="0 1.5707963267948966 0" xyz="0 0 -0.125"/>
      <geometry>
        <box size="0.25 0.0374 0.043"/>
      </geometry>
    </collision>
    <inertial>
      <origin rpy="0 0 0" xyz="-0.005607 0.003877 -0.048199"/>
      <mass value="0.639"/>
      <inertia ixx="0.004173855" ixy="-1.0284e-05" ixz="-0.000318874" iyy="0.004343802" iyz="-0.000109233" izz="0.000340136"/>
    </inertial>
  </link>
  <link name="FR_thigh_rotor">
    <visual>
      <origin rpy="1.5707963267948966 0 0" xyz="0 0 0"/>
      <geometry>
        <cylinder length="0.02" radius="0.035"/>
      </geometry>
      <!-- <material name="green"/> -->
    </visual>
    <!-- <collision>
                <origin rpy="${PI/2.0} 0 0" xyz="0 0 0"/>
                <geometry>
                    <cylinder length="0.02" radius="0.035"/>
                </geometry>
            </collision> -->
    <inertial>
      <origin rpy="0 0 0" xyz="0.0 0.0 0.0"/>
      <mass value="0.146"/>
      <inertia ixx="8.3352e-05" ixy="0.0" ixz="0.0" iyy="0.000138702" iyz="0.0" izz="8.3352e-05"/>
    </inertial>
  </link>
  <joint name="FR_calf_joint" type="revolute">
    <origin rpy="0 0 0" xyz="0 0 -0.25"/>
    <parent link="FR_thigh"/>
    <child link="FR_calf"/>
    <axis xyz="0 1 0"/>
    <dynamics damping="0" friction="0"/>
    <limit effort="44.4" lower="-2.775073510670984" upper="-0.6457718232379019" velocity="15.89"/>
  </joint>
  <joint name="FR_calf_rotor_joint" type="fixed">
    <origin rpy="0 0 0" xyz="0.0 0.0997 0"/>
    <parent link="FR_thigh"/>
    <child link="FR_calf_rotor"/>
  </joint>
  <link name="FR_calf">
    <visual>
      <origin rpy="0 0 0" xyz="0 0 0"/>
      <geometry>
        <mesh filename="meshes/visual/calf.dae" scale="1 1 1"/>
      </geometry>
      <!-- <material name="orange"/> -->
    </visual>
    <collision>
      <origin rpy="0 1.5707963267948966 0" xyz="0 0 -0.125"/>
      <geometry>
        <box size="0.25 0.0208 0.016"/>
      </geometry>
    </collision>
    <inertial>
      <origin rpy="0 0 0" xyz="0.002781 6.3e-05 -0.142518"/>
      <mass value="0.207"/>
      <inertia ixx="0.002129279" ixy="3.9e-08" ixz="5.757e-06" iyy="0.002141463" iyz="-5.16e-07" izz="3.7583e-05"/>
    </inertial>
  </link>
  <link name="FR_calf_rotor">
    <visual>
      <origin rpy="1.5707963267948966 0 0" xyz="0 0 0"/>
      <geometry>
        <cylinder length="0.02" radius="0.035"/>
      </geometry>
      <!-- <material name="green"/> -->
    </visual>
    <!-- <collision>
                <origin rpy="${PI/2.0} 0 0" xyz="0 0 0"/>
                <geometry>
                    <cylinder length="0.02" radius="0.035"/>
                </geometry>
            </collision> -->
    <inertial>
      <origin rpy="0 0 0" xyz="0.0 0.0 0.0"/>
      <mass value="0.132"/>
      <inertia ixx="0.000145463" ixy="0.0" ixz="0.0" iyy="0.000133031" iyz="0.0" izz="0.000145463"/>
    </inertial>
  </link>
  <joint name="FR_foot_fixed" type="fixed">
    <origin rpy="0 0 0" xyz="0 0 -0.25"/>
    <parent link="FR_calf"/>
    <child link="FR_foot"/>
  </joint>
  <link name="FR_foot">
    <visual>
      <origin rpy="0 0 0" xyz="0 0 0"/>
      <geometry>
        <sphere radius="0.0165"/>
      </geometry>
      <!-- <material name="green"/> -->
    </visual>
    <collision>
      <origin rpy="0 0 0" xyz="0 0 0"/>
      <geometry>
        <sphere radius="0.0265"/>
      </geometry>
    </collision>
    <inertial>
      <mass value="0.06"/>
      <inertia ixx="1.6853999999999998e-05" ixy="0.0" ixz="0.0" iyy="1.6853999999999998e-05" iyz="0.0" izz="1.6853999999999998e-05"/>
    </inertial>
  </link>
  <transmission name="FR_hip_tran">
    <type>transmission_interface/SimpleTransmission</type>
    <joint name="FR_hip_joint">
      <hardwareInterface>hardware_interface/EffortJointInterface</hardwareInterface>
    </joint>
    <actuator name="FR_hip_motor">
      <hardwareInterface>hardware_interface/EffortJointInterface</hardwareInterface>
      <mechanicalReduction>1</mechanicalReduction>
    </actuator>
  </transmission>
  <transmission name="FR_thigh_tran">
    <type>transmission_interface/SimpleTransmission</type>
    <joint name="FR_thigh_joint">
      <hardwareInterface>hardware_interface/EffortJointInterface</hardwareInterface>
    </joint>
    <actuator name="FR_thigh_motor">
      <hardwareInterface>hardware_interface/EffortJointInterface</hardwareInterface>
      <mechanicalReduction>1</mechanicalReduction>
    </actuator>
  </transmission>
  <transmission name="FR_calf_tran">
    <type>transmission_interface/SimpleTransmission</type>
    <joint name="FR_calf_joint">
      <hardwareInterface>hardware_interface/EffortJointInterface</hardwareInterface>
    </joint>
    <actuator name="FR_calf_motor">
      <hardwareInterface>hardware_interface/EffortJointInterface</hardwareInterface>
      <mechanicalReduction>1</mechanicalReduction>
    </actuator>
  </transmission>
  <joint name="FL_hip_joint" type="revolute">
    <origin rpy="0 0 0" xyz="0.2407 0.051 0"/>
    <parent link="trunk"/>
    <child link="FL_hip"/>
    <axis xyz="1 0 0"/>
    <dynamics damping="0" friction="0"/>
    <limit effort="35.278" lower="-1.2217304763960306" upper="1.2217304763960306" velocity="20"/>
  </joint>
  <joint name="FL_hip_rotor_joint" type="fixed">
    <origin rpy="0 0 0" xyz="0.139985 0.051 0"/>
    <parent link="trunk"/>
    <child link="FL_hip_rotor"/>
  </joint>
  <link name="FL_hip">
    <visual>
      <origin rpy="0 0 0" xyz="0 0 0"/>
      <geometry>
        <mesh filename="meshes/visual/hip.dae" scale="1 1 1"/>
      </geometry>
      <!-- <material name="orange"/> -->
    </visual>
    <collision>
      <origin rpy="1.5707963267948966 0 0" xyz="0 0.083 0"/>
      <geometry>
        <cylinder length="0.0418" radius="0.046"/>
      </geometry>
    </collision>
    <inertial>
      <origin rpy="0 0 0" xyz="-0.022191 0.015144 -1.5e-05"/>
      <mass value="1.993"/>
      <inertia ixx="0.002446735" ixy="-0.00059805" ixz="1.945e-06" iyy="0.003925876" iyz="1.284e-06" izz="0.004148145"/>
    </inertial>
  </link>
  <link name="FL_hip_rotor">
    <visual>
      <origin rpy="0 1.5707963267948966 0" xyz="0 0 0"/>
      <geometry>
        <cylinder length="0.02" radius="0.035"/>
      </geometry>
      <!-- <material name="green"/> -->
    </visual>
    <!-- <collision>
                <origin rpy="0 ${PI/2.0} 0" xyz="0 0 0"/>
                <geometry>
                    <cylinder length="0.02" radius="0.035"/>
                </geometry>
            </collision> -->
    <inertial>
      <origin rpy="0 0 0" xyz="0.0 0.0 0.0"/>
      <mass value="0.146"/>
      <inertia ixx="0.000138702" ixy="0.0" ixz="0.0" iyy="8.3352e-05" iyz="0.0" izz="8.3352e-05"/>
    </inertial>
  </link>
  <joint name="FL_thigh_joint" type="continuous">
    <origin rpy="0 0 0" xyz="0 0.0868 0"/>
    <parent link="FL_hip"/>
    <child link="FL_thigh"/>
    <axis xyz="0 1 0"/>
    <dynamics damping="0" friction="0"/>
    <limit effort="35.278" velocity="20"/>
  </joint>
  <joint name="FL_thigh_rotor_joint" type="fixed">
    <origin rpy="0 0 0" xyz="0.0 0.0298 0"/>
    <parent link="FL_hip"/>
    <child link="FL_thigh_rotor"/>
  </joint>
  <link name="FL_thigh">
    <visual>
      <origin rpy="0 0 0" xyz="0 0 0"/>
      <geometry>
        <mesh filename="meshes/visual/thigh.dae" scale="1 1 1"/>
      </geometry>
      <!-- <material name="orange"/> -->
    </visual>
    <collision>
      <origin rpy="0 1.5707963267948966 0" xyz="0 0 -0.125"/>
      <geometry>
        <box size="0.25 0.0374 0.043"/>
      </geometry>
    </collision>
    <inertial>
      <origin rpy="0 0 0" xyz="-0.005607 -0.003877 -0.048199"/>
      <mass value="0.639"/>
      <inertia ixx="0.004173855" ixy="1.0284e-05" ixz="-0.000318874" iyy="0.004343802" iyz="0.000109233" izz="0.000340136"/>
    </inertial>
  </link>
  <link name="FL_thigh_rotor">
    <visual>
      <origin rpy="1.5707963267948966 0 0" xyz="0 0 0"/>
      <geometry>
        <cylinder length="0.02" radius="0.035"/>
      </geometry>
      <!-- <material name="green"/> -->
    </visual>
    <!-- <collision>
                <origin rpy="${PI/2.0} 0 0" xyz="0 0 0"/>
                <geometry>
                    <cylinder length="0.02" radius="0.035"/>
                </geometry>
            </collision> -->
    <inertial>
      <origin rpy="0 0 0" xyz="0.0 0.0 0.0"/>
      <mass value="0.146"/>
      <inertia ixx="8.3352e-05" ixy="0.0" ixz="0.0" iyy="0.000138702" iyz="0.0" izz="8.3352e-05"/>
    </inertial>
  </link>
  <joint name="FL_calf_joint" type="revolute">
    <origin rpy="0 0 0" xyz="0 0 -0.25"/>
    <parent link="FL_thigh"/>
    <child link="FL_calf"/>
    <axis xyz="0 1 0"/>
    <dynamics damping="0" friction="0"/>
    <limit effort="44.4" lower="-2.775073510670984" upper="-0.6457718232379019" velocity="15.89"/>
  </joint>
  <joint name="FL_calf_rotor_joint" type="fixed">
    <origin rpy="0 0 0" xyz="0.0 -0.0997 0"/>
    <parent link="FL_thigh"/>
    <child link="FL_calf_rotor"/>
  </joint>
  <link name="FL_calf">
    <visual>
      <origin rpy="0 0 0" xyz="0 0 0"/>
      <geometry>
        <mesh filename="meshes/visual/calf.dae" scale="1 1 1"/>
      </geometry>
      <!-- <material name="orange"/> -->
    </visual>
    <collision>
      <origin rpy="0 1.5707963267948966 0" xyz="0 0 -0.125"/>
      <geometry>
        <box size="0.25 0.0208 0.016"/>
      </geometry>
    </collision>
    <inertial>
      <origin rpy="0 0 0" xyz="0.002781 6.3e-05 -0.142518"/>
      <mass value="0.207"/>
      <inertia ixx="0.002129279" ixy="3.9e-08" ixz="5.757e-06" iyy="0.002141463" iyz="-5.16e-07" izz="3.7583e-05"/>
    </inertial>
  </link>
  <link name="FL_calf_rotor">
    <visual>
      <origin rpy="1.5707963267948966 0 0" xyz="0 0 0"/>
      <geometry>
        <cylinder length="0.02" radius="0.035"/>
      </geometry>
      <!-- <material name="green"/> -->
    </visual>
    <!-- <collision>
                <origin rpy="${PI/2.0} 0 0" xyz="0 0 0"/>
                <geometry>
                    <cylinder length="0.02" radius="0.035"/>
                </geometry>
            </collision> -->
    <inertial>
      <origin rpy="0 0 0" xyz="0.0 0.0 0.0"/>
      <mass value="0.132"/>
      <inertia ixx="0.000145463" ixy="0.0" ixz="0.0" iyy="0.000133031" iyz="0.0" izz="0.000145463"/>
    </inertial>
  </link>
  <joint name="FL_foot_fixed" type="fixed">
    <origin rpy="0 0 0" xyz="0 0 -0.25"/>
    <parent link="FL_calf"/>
    <child link="FL_foot"/>
  </joint>
  <link name="FL_foot">
    <visual>
      <origin rpy="0 0 0" xyz="0 0 0"/>
      <geometry>
        <sphere radius="0.0165"/>
      </geometry>
      <!-- <material name="green"/> -->
    </visual>
    <collision>
      <origin rpy="0 0 0" xyz="0 0 0"/>
      <geometry>
        <sphere radius="0.0265"/>
      </geometry>
    </collision>
    <inertial>
      <mass value="0.06"/>
      <inertia ixx="1.6853999999999998e-05" ixy="0.0" ixz="0.0" iyy="1.6853999999999998e-05" iyz="0.0" izz="1.6853999999999998e-05"/>
    </inertial>
  </link>
  <transmission name="FL_hip_tran">
    <type>transmission_interface/SimpleTransmission</type>
    <joint name="FL_hip_joint">
      <hardwareInterface>hardware_interface/EffortJointInterface</hardwareInterface>
    </joint>
    <actuator name="FL_hip_motor">
      <hardwareInterface>hardware_interface/EffortJointInterface</hardwareInterface>
      <mechanicalReduction>1</mechanicalReduction>
    </actuator>
  </transmission>
  <transmission name="FL_thigh_tran">
    <type>transmission_interface/SimpleTransmission</type>
    <joint name="FL_thigh_joint">
      <hardwareInterface>hardware_interface/EffortJointInterface</hardwareInterface>
    </joint>
    <actuator name="FL_thigh_motor">
      <hardwareInterface>hardware_interface/EffortJointInterface</hardwareInterface>
      <mechanicalReduction>1</mechanicalReduction>
    </actuator>
  </transmission>
  <transmission name="FL_calf_tran">
    <type>transmission_interface/SimpleTransmission</type>
    <joint name="FL_calf_joint">
      <hardwareInterface>hardware_interface/EffortJointInterface</hardwareInterface>
    </joint>
    <actuator name="FL_calf_motor">
      <hardwareInterface>hardware_interface/EffortJointInterface</hardwareInterface>
      <mechanicalReduction>1</mechanicalReduction>
    </actuator>
  </transmission>
  <joint name="RR_hip_joint" type="revolute">
    <origin rpy="0 0 0" xyz="-0.2407 -0.051 0"/>
    <parent link="trunk"/>
    <child link="RR_hip"/>
    <axis xyz="1 0 0"/>
    <dynamics damping="0" friction="0"/>
    <limit effort="35.278" lower="-1.2217304763960306" upper="1.2217304763960306" velocity="20"/>
  </joint>
  <joint name="RR_hip_rotor_joint" type="fixed">
    <origin rpy="0 0 0" xyz="-0.139985 -0.051 0"/>
    <parent link="trunk"/>
    <child link="RR_hip_rotor"/>
  </joint>
  <link name="RR_hip">
    <visual>
      <origin rpy="3.141592653589793 3.141592653589793 0" xyz="0 0 0"/>
      <geometry>
        <mesh filename="meshes/visual/hip.dae" scale="1 1 1"/>
      </geometry>
      <!-- <material name="orange"/> -->
    </visual>
    <collision>
      <origin rpy="1.5707963267948966 0 0" xyz="0 -0.083 0"/>
      <geometry>
        <cylinder length="0.0418" radius="0.046"/>
      </geometry>
    </collision>
    <inertial>
      <origin rpy="0 0 0" xyz="0.022191 -0.015144 -1.5e-05"/>
      <mass value="1.993"/>
      <inertia ixx="0.002446735" ixy="-0.00059805" ixz="-1.945e-06" iyy="0.003925876" iyz="-1.284e-06" izz="0.004148145"/>
    </inertial>
  </link>
  <link name="RR_hip_rotor">
    <visual>
      <origin rpy="0 1.5707963267948966 0" xyz="0 0 0"/>
      <geometry>
        <cylinder length="0.02" radius="0.035"/>
      </geometry>
      <!-- <material name="green"/> -->
    </visual>
    <!-- <collision>
                <origin rpy="0 ${PI/2.0} 0" xyz="0 0 0"/>
                <geometry>
                    <cylinder length="0.02" radius="0.035"/>
                </geometry>
            </collision> -->
    <inertial>
      <origin rpy="0 0 0" xyz="0.0 0.0 0.0"/>
      <mass value="0.146"/>
      <inertia ixx="0.000138702" ixy="0.0" ixz="0.0" iyy="8.3352e-05" iyz="0.0" izz="8.3352e-05"/>
    </inertial>
  </link>
  <joint name="RR_thigh_joint" type="continuous">
    <origin rpy="0 0 0" xyz="0 -0.0868 0"/>
    <parent link="RR_hip"/>
    <child link="RR_thigh"/>
    <axis xyz="0 1 0"/>
    <dynamics damping="0" friction="0"/>
    <limit effort="35.278" velocity="20"/>
  </joint>
  <joint name="RR_thigh_rotor_joint" type="fixed">
    <origin rpy="0 0 0" xyz="0.0 -0.0298 0"/>
    <parent link="RR_hip"/>
    <child link="RR_thigh_rotor"/>
  </joint>
  <link name="RR_thigh">
    <visual>
      <origin rpy="0 0 0" xyz="0 0 0"/>
      <geometry>
        <mesh filename="meshes/visual/thigh_mirror.dae" scale="1 1 1"/>
      </geometry>
      <!-- <material name="orange"/> -->
    </visual>
    <collision>
      <origin rpy="0 1.5707963267948966 0" xyz="0 0 -0.125"/>
      <geometry>
        <box size="0.25 0.0374 0.043"/>
      </geometry>
    </collision>
    <inertial>
      <origin rpy="0 0 0" xyz="-0.005607 0.003877 -0.048199"/>
      <mass value="0.639"/>
      <inertia ixx="0.004173855" ixy="-1.0284e-05" ixz="-0.000318874" iyy="0.004343802" iyz="-0.000109233" izz="0.000340136"/>
    </inertial>
  </link>
  <link name="RR_thigh_rotor">
    <visual>
      <origin rpy="1.5707963267948966 0 0" xyz="0 0 0"/>
      <geometry>
        <cylinder length="0.02" radius="0.035"/>
      </geometry>
      <!-- <material name="green"/> -->
    </visual>
    <!-- <collision>
                <origin rpy="${PI/2.0} 0 0" xyz="0 0 0"/>
                <geometry>
                    <cylinder length="0.02" radius="0.035"/>
                </geometry>
            </collision> -->
    <inertial>
      <origin rpy="0 0 0" xyz="0.0 0.0 0.0"/>
      <mass value="0.146"/>
      <inertia ixx="8.3352e-05" ixy="0.0" ixz="0.0" iyy="0.000138702" iyz="0.0" izz="8.3352e-05"/>
    </inertial>
  </link>
  <joint name="RR_calf_joint" type="revolute">
    <origin rpy="0 0 0" xyz="0 0 -0.25"/>
    <parent link="RR_thigh"/>
    <child link="RR_calf"/>
    <axis xyz="0 1 0"/>
    <dynamics damping="0" friction="0"/>
    <limit effort="44.4" lower="-2.775073510670984" upper="-0.6457718232379019" velocity="15.89"/>
  </joint>
  <joint name="RR_calf_rotor_joint" type="fixed">
    <origin rpy="0 0 0" xyz="0.0 0.0997 0"/>
    <parent link="RR_thigh"/>
    <child link="RR_calf_rotor"/>
  </joint>
  <link name="RR_calf">
    <visual>
      <origin rpy="0 0 0" xyz="0 0 0"/>
      <geometry>
        <mesh filename="meshes/visual/calf.dae" scale="1 1 1"/>
      </geometry>
      <!-- <material name="orange"/> -->
    </visual>
    <collision>
      <origin rpy="0 1.5707963267948966 0" xyz="0 0 -0.125"/>
      <geometry>
        <box size="0.25 0.0208 0.016"/>
      </geometry>
    </collision>
    <inertial>
      <origin rpy="0 0 0" xyz="0.002781 6.3e-05 -0.142518"/>
      <mass value="0.207"/>
      <inertia ixx="0.002129279" ixy="3.9e-08" ixz="5.757e-06" iyy="0.002141463" iyz="-5.16e-07" izz="3.7583e-05"/>
    </inertial>
  </link>
  <link name="RR_calf_rotor">
    <visual>
      <origin rpy="1.5707963267948966 0 0" xyz="0 0 0"/>
      <geometry>
        <cylinder length="0.02" radius="0.035"/>
      </geometry>
      <!-- <material name="green"/> -->
    </visual>
    <!-- <collision>
                <origin rpy="${PI/2.0} 0 0" xyz="0 0 0"/>
                <geometry>
                    <cylinder length="0.02" radius="0.035"/>
                </geometry>
            </collision> -->
    <inertial>
      <origin rpy="0 0 0" xyz="0.0 0.0 0.0"/>
      <mass value="0.132"/>
      <inertia ixx="0.000145463" ixy="0.0" ixz="0.0" iyy="0.000133031" iyz="0.0" izz="0.000145463"/>
    </inertial>
  </link>
  <joint name="RR_foot_fixed" type="fixed">
    <origin rpy="0 0 0" xyz="0 0 -0.25"/>
    <parent link="RR_calf"/>
    <child link="RR_foot"/>
  </joint>
  <link name="RR_foot">
    <visual>
      <origin rpy="0 0 0" xyz="0 0 0"/>
      <geometry>
        <sphere radius="0.0165"/>
      </geometry>
      <!-- <material name="green"/> -->
    </visual>
    <collision>
      <origin rpy="0 0 0" xyz="0 0 0"/>
      <geometry>
        <sphere radius="0.0265"/>
      </geometry>
    </collision>
    <inertial>
      <mass value="0.06"/>
      <inertia ixx="1.6853999999999998e-05" ixy="0.0" ixz="0.0" iyy="1.6853999999999998e-05" iyz="0.0" izz="1.6853999999999998e-05"/>
    </inertial>
  </link>
  <transmission name="RR_hip_tran">
    <type>transmission_interface/SimpleTransmission</type>
    <joint name="RR_hip_joint">
      <hardwareInterface>hardware_interface/EffortJointInterface</hardwareInterface>
    </joint>
    <actuator name="RR_hip_motor">
      <hardwareInterface>hardware_interface/EffortJointInterface</hardwareInterface>
      <mechanicalReduction>1</mechanicalReduction>
    </actuator>
  </transmission>
  <transmission name="RR_thigh_tran">
    <type>transmission_interface/SimpleTransmission</type>
    <joint name="RR_thigh_joint">
      <hardwareInterface>hardware_interface/EffortJointInterface</hardwareInterface>
    </joint>
    <actuator name="RR_thigh_motor">
      <hardwareInterface>hardware_interface/EffortJointInterface</hardwareInterface>
      <mechanicalReduction>1</mechanicalReduction>
    </actuator>
  </transmission>
  <transmission name="RR_calf_tran">
    <type>transmission_interface/SimpleTransmission</type>
    <joint name="RR_calf_joint">
      <hardwareInterface>hardware_interface/EffortJointInterface</hardwareInterface>
    </joint>
    <actuator name="RR_calf_motor">
      <hardwareInterface>hardware_interface/EffortJointInterface</hardwareInterface>
      <mechanicalReduction>1</mechanicalReduction>
    </actuator>
  </transmission>
  <joint name="RL_hip_joint" type="revolute">
    <origin rpy="0 0 0" xyz="-0.2407 0.051 0"/>
    <parent link="trunk"/>
    <child link="RL_hip"/>
    <axis xyz="1 0 0"/>
    <dynamics damping="0" friction="0"/>
    <limit effort="35.278" lower="-1.2217304763960306" upper="1.2217304763960306" velocity="20"/>
  </joint>
  <joint name="RL_hip_rotor_joint" type="fixed">
    <origin rpy="0 0 0" xyz="-0.139985 0.051 0"/>
    <parent link="trunk"/>
    <child link="RL_hip_rotor"/>
  </joint>
  <link name="RL_hip">
    <visual>
      <origin rpy="0 3.141592653589793 0" xyz="0 0 0"/>
      <geometry>
        <mesh filename="meshes/visual/hip.dae" scale="1 1 1"/>
      </geometry>
      <!-- <material name="orange"/> -->
    </visual>
    <collision>
      <origin rpy="1.5707963267948966 0 0" xyz="0 0.083 0"/>
      <geometry>
        <cylinder length="0.0418" radius="0.046"/>
      </geometry>
    </collision>
    <inertial>
      <origin rpy="0 0 0" xyz="0.022191 0.015144 -1.5e-05"/>
      <mass value="1.993"/>
      <inertia ixx="0.002446735" ixy="0.00059805" ixz="-1.945e-06" iyy="0.003925876" iyz="1.284e-06" izz="0.004148145"/>
    </inertial>
  </link>
  <link name="RL_hip_rotor">
    <visual>
      <origin rpy="0 1.5707963267948966 0" xyz="0 0 0"/>
      <geometry>
        <cylinder length="0.02" radius="0.035"/>
      </geometry>
      <!-- <material name="green"/> -->
    </visual>
    <!-- <collision>
                <origin rpy="0 ${PI/2.0} 0" xyz="0 0 0"/>
                <geometry>
                    <cylinder length="0.02" radius="0.035"/>
                </geometry>
            </collision> -->
    <inertial>
      <origin rpy="0 0 0" xyz="0.0 0.0 0.0"/>
      <mass value="0.146"/>
      <inertia ixx="0.000138702" ixy="0.0" ixz="0.0" iyy="8.3352e-05" iyz="0.0" izz="8.3352e-05"/>
    </inertial>
  </link>
  <joint name="RL_thigh_joint" type="continuous">
    <origin rpy="0 0 0" xyz="0 0.0868 0"/>
    <parent link="RL_hip"/>
    <child link="RL_thigh"/>
    <axis xyz="0 1 0"/>
    <dynamics damping="0" friction="0"/>
    <limit effort="35.278" velocity="20"/>
  </joint>
  <joint name="RL_thigh_rotor_joint" type="fixed">
    <origin rpy="0 0 0" xyz="0.0 0.0298 0"/>
    <parent link="RL_hip"/>
    <child link="RL_thigh_rotor"/>
  </joint>
  <link name="RL_thigh">
    <visual>
      <origin rpy="0 0 0" xyz="0 0 0"/>
      <geometry>
        <mesh filename="meshes/visual/thigh.dae" scale="1 1 1"/>
      </geometry>
      <!-- <material name="orange"/> -->
    </visual>
    <collision>
      <origin rpy="0 1.5707963267948966 0" xyz="0 0 -0.125"/>
      <geometry>
        <box size="0.25 0.0374 0.043"/>
      </geometry>
    </collision>
    <inertial>
      <origin rpy="0 0 0" xyz="-0.005607 -0.003877 -0.048199"/>
      <mass value="0.639"/>
      <inertia ixx="0.004173855" ixy="1.0284e-05" ixz="-0.000318874" iyy="0.004343802" iyz="0.000109233" izz="0.000340136"/>
    </inertial>
  </link>
  <link name="RL_thigh_rotor">
    <visual>
      <origin rpy="1.5707963267948966 0 0" xyz="0 0 0"/>
      <geometry>
        <cylinder length="0.02" radius="0.035"/>
      </geometry>
      <!-- <material name="green"/> -->
    </visual>
    <!-- <collision>
                <origin rpy="${PI/2.0} 0 0" xyz="0 0 0"/>
                <geometry>
                    <cylinder length="0.02" radius="0.035"/>
                </geometry>
            </collision> -->
    <inertial>
      <origin rpy="0 0 0" xyz="0.0 0.0 0.0"/>
      <mass value="0.146"/>
      <inertia ixx="8.3352e-05" ixy="0.0" ixz="0.0" iyy="0.000138702" iyz="0.0" izz="8.3352e-05"/>
    </inertial>
  </link>
  <joint name="RL_calf_joint" type="revolute">
    <origin rpy="0 0 0" xyz="0 0 -0.25"/>
    <parent link="RL_thigh"/>
    <child link="RL_calf"/>
    <axis xyz="0 1 0"/>
    <dynamics damping="0" friction="0"/>
    <limit effort="44.4" lower="-2.775073510670984" upper="-0.6457718232379019" velocity="15.89"/>
  </joint>
  <joint name="RL_calf_rotor_joint" type="fixed">
    <origin rpy="0 0 0" xyz="0.0 -0.0997 0"/>
    <parent link="RL_thigh"/>
    <child link="RL_calf_rotor"/>
  </joint>
  <link name="RL_calf">
    <visual>
      <origin rpy="0 0 0" xyz="0 0 0"/>
      <geometry>
        <mesh filename="meshes/visual/calf.dae" scale="1 1 1"/>
      </geometry>
      <!-- <material name="orange"/> -->
    </visual>
    <collision>
      <origin rpy="0 1.5707963267948966 0" xyz="0 0 -0.125"/>
      <geometry>
        <box size="0.25 0.0208 0.016"/>
      </geometry>
    </collision>
    <inertial>
      <origin rpy="0 0 0" xyz="0.002781 6.3e-05 -0.142518"/>
      <mass value="0.207"/>
      <inertia ixx="0.002129279" ixy="3.9e-08" ixz="5.757e-06" iyy="0.002141463" iyz="-5.16e-07" izz="3.7583e-05"/>
    </inertial>
  </link>
  <link name="RL_calf_rotor">
    <visual>
      <origin rpy="1.5707963267948966 0 0" xyz="0 0 0"/>
      <geometry>
        <cylinder length="0.02" radius="0.035"/>
      </geometry>
      <!-- <material name="green"/> -->
    </visual>
    <!-- <collision>
                <origin rpy="${PI/2.0} 0 0" xyz="0 0 0"/>
                <geometry>
                    <cylinder length="0.02" radius="0.035"/>
                </geometry>
            </collision> -->
    <inertial>
      <origin rpy="0 0 0" xyz="0.0 0.0 0.0"/>
      <mass value="0.132"/>
      <inertia ixx="0.000145463" ixy="0.0" ixz="0.0" iyy="0.000133031" iyz="0.0" izz="0.000145463"/>
    </inertial>
  </link>
  <joint name="RL_foot_fixed" type="fixed">
    <origin rpy="0 0 0" xyz="0 0 -0.25"/>
    <parent link="RL_calf"/>
    <child link="RL_foot"/>
  </joint>
  <link name="RL_foot">
    <visual>
      <origin rpy="0 0 0" xyz="0 0 0"/>
      <geometry>
        <sphere radius="0.0165"/>
      </geometry>
      <!-- <material name="green"/> -->
    </visual>
    <collision>
      <origin rpy="0 0 0" xyz="0 0 0"/>
      <geometry>
        <sphere radius="0.0265"/>
      </geometry>
    </collision>
    <inertial>
      <mass value="0.06"/>
      <inertia ixx="1.6853999999999998e-05" ixy="0.0" ixz="0.0" iyy="1.6853999999999998e-05" iyz="0.0" izz="1.6853999999999998e-05"/>
    </inertial>
  </link>
  <transmission name="RL_hip_tran">
    <type>transmission_interface/SimpleTransmission</type>
    <joint name="RL_hip_joint">
      <hardwareInterface>hardware_interface/EffortJointInterface</hardwareInterface>
    </joint>
    <actuator name="RL_hip_motor">
      <hardwareInterface>hardware_interface/EffortJointInterface</hardwareInterface>
      <mechanicalReduction>1</mechanicalReduction>
    </actuator>
  </transmission>
  <transmission name="RL_thigh_tran">
    <type>transmission_interface/SimpleTransmission</type>
    <joint name="RL_thigh_joint">
      <hardwareInterface>hardware_interface/EffortJointInterface</hardwareInterface>
    </joint>
    <actuator name="RL_thigh_motor">
      <hardwareInterface>hardware_interface/EffortJointInterface</hardwareInterface>
      <mechanicalReduction>1</mechanicalReduction>
    </actuator>
  </transmission>
  <transmission name="RL_calf_tran">
    <type>transmission_interface/SimpleTransmission</type>
    <joint name="RL_calf_joint">
      <hardwareInterface>hardware_interface/EffortJointInterface</hardwareInterface>
    </joint>
    <actuator name="RL_calf_motor">
      <hardwareInterface>hardware_interface/EffortJointInterface</hardwareInterface>
      <mechanicalReduction>1</mechanicalReduction>
    </actuator>
  </transmission>
</robot>
